Workbook

Sheet Transactions
A1: Date | B1: Bank Type | C1: Description | D1: Original Amount (£) | E1: Direction | F1: Payment Method | G1: Category | H1: Subcategory / Detail | I1: Business Status | J1: Business Use % | K1: Allowable? | L1: Allowable Income (£) | M1: Allowable Expense (£) | N1: VAT Treatment | O1: Receipt Status | P1: Receipt / File Link | Q1: Bike / Job Ref | R1: MTD Quarter | S1: Notes | T1: Accountant Review | U1: Bank Balance (£)
A2: 45901 | B2: BP | C2: Dan byrne natwest Post office | D2: -9.85 | E2: Expense | F2: Bank Transfer | G2: Postage and Courier | I2: Business | J2: 1 | K2: Yes | L2: =IF(AND($E2="Income",$I2="Business",$K2="Yes"),MAX($D2,0)*$J2,0) -> 0 | M2: =IF(AND($E2="Expense",OR($I2="Business",$I2="Mixed"),OR($K2="Yes",$K2="Stock")),ABS(MIN($D2,0))*$J2,0) -> 9.85 | N2: No VAT registered | O2: To find | R2: Outside 2026–27 | T2: Not reviewed | U2: 850.15
A3: 45901 | B3: CR | C3: Premium Parts Pcx | D3: 160 | E3: Income | F3: Bank Transfer | G3: Other Business Income | I3: Business | J3: 1 | K3: Yes | L3: =IF(AND($E3="Income",$I3="Business",$K3="Yes"),MAX($D3,0)*$J3,0) -> 160 | M3: =IF(AND($E3="Expense",OR($I3="Business",$I3="Mixed"),OR($K3="Yes",$K3="Stock")),ABS(MIN($D3,0))*$J3,0) -> 0 | N3: No VAT registered | O3: To find | R3: Outside 2026–27 | T3: Not reviewed | U3: 860
A4: 45901 | B4: BP | C4: Sell your motobikePurchace | D4: -1800 | E4: Expense | F4: Bank Transfer | G4: Bike Purchases (Stock) | I4: Business | J4: 1 | K4: Stock | L4: =IF(AND($E4="Income",$I4="Business",$K4="Yes"),MAX($D4,0)*$J4,0) -> 0 | M4: =IF(AND($E4="Expense",OR($I4="Business",$I4="Mixed"),OR($K4="Yes",$K4="Stock")),ABS(MIN($D4,0))*$J4,0) -> 1800 | N4: No VAT registered | O4: To find | R4: Outside 2026–27 | T4: Not reviewed | U4: 700
A5: 45901 | B5: CR | C5: DANIEL WILLIA CP Startup | D5: 2500 | E5: Income | F5: Bank Transfer | G5: Other Business Income | I5: Business | J5: 1 | K5: Yes | L5: =IF(AND($E5="Income",$I5="Business",$K5="Yes"),MAX($D5,0)*$J5,0) -> 2500 | M5: =IF(AND($E5="Expense",OR($I5="Business",$I5="Mixed"),OR($K5="Yes",$K5="Stock")),ABS(MIN($D5,0))*$J5,0) -> 0 | N5: No VAT registered | O5: To find | R5: Outside 2026–27 | T5: Not reviewed | U5: 2500
A6: 45903 | B6: BP | C6: Dan byrne natwest Post office | D6: -9.85 | E6: Expense | F6: Bank Transfer | G6: Postage and Courier | I6: Business | J6: 1 | K6: Yes | L6: =IF(AND($E6="Income",$I6="Business",$K6="Yes"),MAX($D6,0)*$J6,0) -> 0 | M6: =IF(AND($E6="Expense",OR($I6="Business",$I6="Mixed"),OR($K6="Yes",$K6="Stock")),ABS(MIN($D6,0))*$J6,0) -> 9.85 | N6: No VAT registered | O6: To find | R6: Outside 2026–27 | T6: Not reviewed | U6: 840.3
A7: 45903 | B7: CR | C7: DEMETRIS ED BIKE | D7: 350 | E7: Income | F7: Bank Transfer | G7: Other Business Income | I7: Business | J7: 1 | K7: Yes | L7: =IF(AND($E7="Income",$I7="Business",$K7="Yes"),MAX($D7,0)*$J7,0) -> 350 | M7: =IF(AND($E7="Expense",OR($I7="Business",$I7="Mixed"),OR($K7="Yes",$K7="Stock")),ABS(MIN($D7,0))*$J7,0) -> 0 | N7: No VAT registered | O7: To find | R7: Outside 2026–27 | T7: Not reviewed | U7: 850.15
A8: 45903 | B8: BP | C8: Christian Mutt mj68mxu | D8: -350 | E8: Expense | F8: Bank Transfer | G8: Bike Purchases (Stock) | I8: Business | J8: 1 | K8: Stock | L8: =IF(AND($E8="Income",$I8="Business",$K8="Yes"),MAX($D8,0)*$J8,0) -> 0 | M8: =IF(AND($E8="Expense",OR($I8="Business",$I8="Mixed"),OR($K8="Yes",$K8="Stock")),ABS(MIN($D8,0))*$J8,0) -> 350 | N8: No VAT registered | O8: To find | R8: Outside 2026–27 | T8: Not reviewed | U8: 500.15
A9: 45909 | B9: CR | C9: Atanas Monev KEY | D9: 80 | E9: Income | F9: Bank Transfer | G9: Other Business Income | I9: Business | J9: 1 | K9: Yes | L9: =IF(AND($E9="Income",$I9="Business",$K9="Yes"),MAX($D9,0)*$J9,0) -> 80 | M9: =IF(AND($E9="Expense",OR($I9="Business",$I9="Mixed"),OR($K9="Yes",$K9="Stock")),ABS(MIN($D9,0))*$J9,0) -> 0 | N9: No VAT registered | O9: To find | R9: Outside 2026–27 | T9: Not reviewed | U9: 920.3
A10: 45914 | B10: BP | C10: Travis Deposit return | D10: -100 | E10: Expense | F10: Bank Transfer | G10: Other Business Expense | H10: ignore refund | I10: Business | J10: 1 | K10: No | L10: =IF(AND($E10="Income",$I10="Business",$K10="Yes"),MAX($D10,0)*$J10,0) -> 0 | M10: =IF(AND($E10="Expense",OR($I10="Business",$I10="Mixed"),OR($K10="Yes",$K10="Stock")),ABS(MIN($D10,0))*$J10,0) -> 0 | N10: No VAT registered | O10: To find | R10: Outside 2026–27 | T10: Not reviewed | U10: 920.3
A11: 45914 | B11: CR | C11: D Collins ej12dpn | D11: 100 | E11: Income | F11: Bank Transfer | G11: Other Business Income | H11: ignore deposit | I11: Business | J11: 1 | K11: No | L11: =IF(AND($E11="Income",$I11="Business",$K11="Yes"),MAX($D11,0)*$J11,0) -> 0 | M11: =IF(AND($E11="Expense",OR($I11="Business",$I11="Mixed"),OR($K11="Yes",$K11="Stock")),ABS(MIN($D11,0))*$J11,0) -> 0 | N11: No VAT registered | O11: To find | R11: Outside 2026–27 | T11: Not reviewed | U11: 1020.3
A12: 45915 | B12: ))) | C12: SINNIS MOTORCYCLESBRIGHTON | D12: -12.5 | E12: Expense | F12: Card | G12: Parts and Materials | I12: Business | J12: 1 | K12: Yes | L12: =IF(AND($E12="Income",$I12="Business",$K12="Yes"),MAX($D12,0)*$J12,0) -> 0 | M12: =IF(AND($E12="Expense",OR($I12="Business",$I12="Mixed"),OR($K12="Yes",$K12="Stock")),ABS(MIN($D12,0))*$J12,0) -> 12.5 | N12: No VAT registered | O12: To find | R12: Outside 2026–27 | T12: Not reviewed | U12: 907.8
A13: 45919 | B13: CR | C13: JONATHAN MONKS monks SCUcodekey | D13: 170 | E13: Income | F13: Bank Transfer | G13: Other Business Income | I13: Business | J13: 1 | K13: Yes | L13: =IF(AND($E13="Income",$I13="Business",$K13="Yes"),MAX($D13,0)*$J13,0) -> 170 | M13: =IF(AND($E13="Expense",OR($I13="Business",$I13="Mixed"),OR($K13="Yes",$K13="Stock")),ABS(MIN($D13,0))*$J13,0) -> 0 | N13: No VAT registered | O13: To find | R13: Outside 2026–27 | T13: Not reviewed | U13: 1242.58
A14: 45919 | B14: CR | C14: SHOPIFY INC SHOPIFY /PAYER ACC | D14: 164.78 | E14: Income | F14: Bank Transfer | G14: SmartFobs Sales | I14: Business | J14: 1 | K14: Yes | L14: =IF(AND($E14="Income",$I14="Business",$K14="Yes"),MAX($D14,0)*$J14,0) -> 164.78 | M14: =IF(AND($E14="Expense",OR($I14="Business",$I14="Mixed"),OR($K14="Yes",$K14="Stock")),ABS(MIN($D14,0))*$J14,0) -> 0 | N14: No VAT registered | O14: To find | R14: Outside 2026–27 | T14: Not reviewed | U14: 1072.58
A15: 45920 | B15: CR | C15: NICOLA MANNING bike | D15: 1600 | E15: Income | F15: Bank Transfer | G15: Other Business Income | I15: Business | J15: 1 | K15: Yes | L15: =IF(AND($E15="Income",$I15="Business",$K15="Yes"),MAX($D15,0)*$J15,0) -> 1600 | M15: =IF(AND($E15="Expense",OR($I15="Business",$I15="Mixed"),OR($K15="Yes",$K15="Stock")),ABS(MIN($D15,0))*$J15,0) -> 0 | N15: No VAT registered | O15: To find | R15: Outside 2026–27 | T15: Not reviewed | U15: 2842.58
A16: 45922 | B16: BP | C16: Dan byrne natwest Shopify sub | D16: -25 | E16: Expense | F16: Bank Transfer | G16: Software and Subscriptions | I16: Business | J16: 1 | K16: Yes | L16: =IF(AND($E16="Income",$I16="Business",$K16="Yes"),MAX($D16,0)*$J16,0) -> 0 | M16: =IF(AND($E16="Expense",OR($I16="Business",$I16="Mixed"),OR($K16="Yes",$K16="Stock")),ABS(MIN($D16,0))*$J16,0) -> 25 | N16: No VAT registered | O16: To find | R16: Outside 2026–27 | T16: Not reviewed | U16: 2817.58
A17: 45925 | B17: ))) | C17: SINNIS MOTORCYCLESBRIGHTON | D17: -15 | E17: Expense | F17: Card | G17: Parts and Materials | I17: Business | J17: 1 | K17: Yes | L17: =IF(AND($E17="Income",$I17="Business",$K17="Yes"),MAX($D17,0)*$J17,0) -> 0 | M17: =IF(AND($E17="Expense",OR($I17="Business",$I17="Mixed"),OR($K17="Yes",$K17="Stock")),ABS(MIN($D17,0))*$J17,0) -> 15 | N17: No VAT registered | O17: To find | R17: Outside 2026–27 | T17: Not reviewed | U17: 2802.58
A18: 45927 | B18: CR | C18: CROFT H J TRIUMPH | D18: 2750 | E18: Income | F18: Bank Transfer | G18: Other Business Income | I18: Business | J18: 1 | K18: Yes | L18: =IF(AND($E18="Income",$I18="Business",$K18="Yes"),MAX($D18,0)*$J18,0) -> 2750 | M18: =IF(AND($E18="Expense",OR($I18="Business",$I18="Mixed"),OR($K18="Yes",$K18="Stock")),ABS(MIN($D18,0))*$J18,0) -> 0 | N18: No VAT registered | O18: To find | R18: Outside 2026–27 | T18: Not reviewed | U18: 5552.58
A19: 45928 | B19: BP | C19: Sell your motobikePurchace | D19: -1622 | E19: Expense | F19: Bank Transfer | G19: Bike Purchases (Stock) | I19: Business | J19: 1 | K19: Stock | L19: =IF(AND($E19="Income",$I19="Business",$K19="Yes"),MAX($D19,0)*$J19,0) -> 0 | M19: =IF(AND($E19="Expense",OR($I19="Business",$I19="Mixed"),OR($K19="Yes",$K19="Stock")),ABS(MIN($D19,0))*$J19,0) -> 1622 | N19: No VAT registered | O19: To find | R19: Outside 2026–27 | T19: Not reviewed | U19: 3930.58
A20: 45929 | B20: VIS | C20: ALIEXPRESS.COM London | D20: -199.05 | E20: Expense | F20: Card | G20: Tools and Equipment | H20: tooling | I20: Business | J20: 1 | K20: Yes | L20: =IF(AND($E20="Income",$I20="Business",$K20="Yes"),MAX($D20,0)*$J20,0) -> 0 | M20: =IF(AND($E20="Expense",OR($I20="Business",$I20="Mixed"),OR($K20="Yes",$K20="Stock")),ABS(MIN($D20,0))*$J20,0) -> 199.05 | N20: No VAT registered | O20: To find | R20: Outside 2026–27 | T20: Not reviewed | U20: 3799.88
A21: 45929 | B21: CR | C21: SHOPIFY INC SHOPIFY /PAYER ACC | D21: 68.35 | E21: Income | F21: Bank Transfer | G21: SmartFobs Sales | I21: Business | J21: 1 | K21: Yes | L21: =IF(AND($E21="Income",$I21="Business",$K21="Yes"),MAX($D21,0)*$J21,0) -> 68.35 | M21: =IF(AND($E21="Expense",OR($I21="Business",$I21="Mixed"),OR($K21="Yes",$K21="Stock")),ABS(MIN($D21,0))*$J21,0) -> 0 | N21: No VAT registered | O21: To find | R21: Outside 2026–27 | T21: Not reviewed | U21: 3998.93
A22: 45931 | B22: ))) | C22: POST OFFICE COUNTEBRIGHTON | D22: -8.75 | E22: Expense | F22: Card | G22: Postage and Courier | I22: Business | J22: 1 | K22: Yes | L22: =IF(AND($E22="Income",$I22="Business",$K22="Yes"),MAX($D22,0)*$J22,0) -> 0 | M22: =IF(AND($E22="Expense",OR($I22="Business",$I22="Mixed"),OR($K22="Yes",$K22="Stock")),ABS(MIN($D22,0))*$J22,0) -> 8.75 | N22: No VAT registered | O22: To find | R22: Outside 2026–27 | T22: Not reviewed | U22: 3791.13
A23: 45932 | B23: CR | C23: SHOPIFY INC SHOPIFY /PAYER ACC | D23: 78.15 | E23: Income | F23: Bank Transfer | G23: SmartFobs Sales | I23: Business | J23: 1 | K23: Yes | L23: =IF(AND($E23="Income",$I23="Business",$K23="Yes"),MAX($D23,0)*$J23,0) -> 78.15 | M23: =IF(AND($E23="Expense",OR($I23="Business",$I23="Mixed"),OR($K23="Yes",$K23="Stock")),ABS(MIN($D23,0))*$J23,0) -> 0 | N23: No VAT registered | O23: To find | R23: Outside 2026–27 | T23: Not reviewed | U23: 3869.28
A24: 45933 | B24: VIS | C24: easyJetKBBMGQ5 Luton | D24: -53.07 | E24: Expense | F24: Card | G24: Travel and Parking | H24: Business travel – Milan supplier and parts sourcing | I24: Business | J24: 1 | K24: Yes | L24: =IF(AND($E24="Income",$I24="Business",$K24="Yes"),MAX($D24,0)*$J24,0) -> 0 | M24: =IF(AND($E24="Expense",OR($I24="Business",$I24="Mixed"),OR($K24="Yes",$K24="Stock")),ABS(MIN($D24,0))*$J24,0) -> 53.07 | N24: No VAT registered | O24: To find | R24: Outside 2026–27 | S24: Two-day business trip to Milan with Sean to research motorcycle parts and potential products for resale. Sean paid the accommodation. | T24: Not reviewed | U24: 3799.59
A25: 45933 | B25: BP | C25: Dg motorcycles Mot WD22 MWJ | D25: -16.62 | E25: Expense | F25: Bank Transfer | G25: Parts and Materials | I25: Business | J25: 1 | K25: Yes | L25: =IF(AND($E25="Income",$I25="Business",$K25="Yes"),MAX($D25,0)*$J25,0) -> 0 | M25: =IF(AND($E25="Expense",OR($I25="Business",$I25="Mixed"),OR($K25="Yes",$K25="Stock")),ABS(MIN($D25,0))*$J25,0) -> 16.62 | N25: No VAT registered | O25: To find | R25: Outside 2026–27 | T25: Not reviewed | U25: 3852.66
A26: 45938 | B26: DD | C26: SHOPIFY | D26: -80 | E26: Expense | F26: Direct Debit | G26: Software and Subscriptions | I26: Business | J26: 1 | K26: Yes | L26: =IF(AND($E26="Income",$I26="Business",$K26="Yes"),MAX($D26,0)*$J26,0) -> 0 | M26: =IF(AND($E26="Expense",OR($I26="Business",$I26="Mixed"),OR($K26="Yes",$K26="Stock")),ABS(MIN($D26,0))*$J26,0) -> 80 | N26: No VAT registered | O26: To find | R26: Outside 2026–27 | T26: Not reviewed | U26: 3719.59
A27: 45945 | B27: VIS | C27: OVERCLOCKERS UK NEWCASTLE-UND | D27: -475 | E27: Expense | F27: Card | G27: Other Business Expense | H27: new work pc parts | I27: Business | J27: 1 | K27: Yes | L27: =IF(AND($E27="Income",$I27="Business",$K27="Yes"),MAX($D27,0)*$J27,0) -> 0 | M27: =IF(AND($E27="Expense",OR($I27="Business",$I27="Mixed"),OR($K27="Yes",$K27="Stock")),ABS(MIN($D27,0))*$J27,0) -> 475 | N27: No VAT registered | O27: To find | R27: Outside 2026–27 | T27: Not reviewed | U27: 3322.74
A28: 45945 | B28: CR | C28: SHOPIFY INC SHOPIFY /PAYER ACC | D28: 78.15 | E28: Income | F28: Bank Transfer | G28: SmartFobs Sales | I28: Business | J28: 1 | K28: Yes | L28: =IF(AND($E28="Income",$I28="Business",$K28="Yes"),MAX($D28,0)*$J28,0) -> 78.15 | M28: =IF(AND($E28="Expense",OR($I28="Business",$I28="Mixed"),OR($K28="Yes",$K28="Stock")),ABS(MIN($D28,0))*$J28,0) -> 0 | N28: No VAT registered | O28: To find | R28: Outside 2026–27 | T28: Not reviewed | U28: 3797.74
A29: 45946 | B29: CR | C29: SHOPIFY INC SHOPIFY /PAYER ACC | D29: 244.75 | E29: Income | F29: Bank Transfer | G29: SmartFobs Sales | I29: Business | J29: 1 | K29: Yes | L29: =IF(AND($E29="Income",$I29="Business",$K29="Yes"),MAX($D29,0)*$J29,0) -> 244.75 | M29: =IF(AND($E29="Expense",OR($I29="Business",$I29="Mixed"),OR($K29="Yes",$K29="Stock")),ABS(MIN($D29,0))*$J29,0) -> 0 | N29: No VAT registered | O29: To find | R29: Outside 2026–27 | T29: Not reviewed | U29: 3567.49
A30: 45951 | B30: VIS | C30: ALIEXPRESS.COM London | D30: -61.62 | E30: Expense | F30: Card | G30: Keys / Stock / Small Parts | H30: key stock | I30: Business | J30: 1 | K30: Yes | L30: =IF(AND($E30="Income",$I30="Business",$K30="Yes"),MAX($D30,0)*$J30,0) -> 0 | M30: =IF(AND($E30="Expense",OR($I30="Business",$I30="Mixed"),OR($K30="Yes",$K30="Stock")),ABS(MIN($D30,0))*$J30,0) -> 61.62 | N30: No VAT registered | O30: To find | R30: Outside 2026–27 | T30: Not reviewed | U30: 3505.87
A31: 45952 | B31: VIS | C31: AUTO TRADER MANCHESTER | D31: -39.95 | E31: Expense | F31: Card | G31: Advertising and Marketing | H31: cost of advert | I31: Business | J31: 1 | K31: Yes | L31: =IF(AND($E31="Income",$I31="Business",$K31="Yes"),MAX($D31,0)*$J31,0) -> 0 | M31: =IF(AND($E31="Expense",OR($I31="Business",$I31="Mixed"),OR($K31="Yes",$K31="Stock")),ABS(MIN($D31,0))*$J31,0) -> 39.95 | N31: No VAT registered | O31: To find | R31: Outside 2026–27 | T31: Not reviewed | U31: 3465.92
A32: 45959 | B32: CR | C32: Lorenne De Souza | D32: 170 | E32: Income | F32: Bank Transfer | G32: SmartFobs Sales | I32: Business | J32: 1 | K32: Yes | L32: =IF(AND($E32="Income",$I32="Business",$K32="Yes"),MAX($D32,0)*$J32,0) -> 170 | M32: =IF(AND($E32="Expense",OR($I32="Business",$I32="Mixed"),OR($K32="Yes",$K32="Stock")),ABS(MIN($D32,0))*$J32,0) -> 0 | N32: No VAT registered | O32: To find | R32: Outside 2026–27 | T32: Not reviewed | U32: 3635.92
A33: 45966 | B33: DR | C33: Non-Sterling Transaction Fee | D33: -0.19 | E33: Expense | F33: Bank Fee | G33: Travel and Parking | H33: travel expenses | I33: Business | J33: 1 | K33: Yes | L33: =IF(AND($E33="Income",$I33="Business",$K33="Yes"),MAX($D33,0)*$J33,0) -> 0 | M33: =IF(AND($E33="Expense",OR($I33="Business",$I33="Mixed"),OR($K33="Yes",$K33="Stock")),ABS(MIN($D33,0))*$J33,0) -> 0.19 | N33: No VAT registered | O33: To find | R33: Outside 2026–27 | T33: Not reviewed | U33: 3611.55
A34: 45966 | B34: ))) | C34: INT'L 0014421531 FIERA MI RISTORAZIRHO EUR 8.00 @ 1.1379 Visa Rate | D34: -7.03 | E34: Expense | F34: Card | G34: Travel and Parking | H34: travel expenses | I34: Business | J34: 1 | K34: Yes | L34: =IF(AND($E34="Income",$I34="Business",$K34="Yes"),MAX($D34,0)*$J34,0) -> 0 | M34: =IF(AND($E34="Expense",OR($I34="Business",$I34="Mixed"),OR($K34="Yes",$K34="Stock")),ABS(MIN($D34,0))*$J34,0) -> 7.03 | N34: No VAT registered | O34: To find | R34: Outside 2026–27 | T34: Not reviewed | U34: 3611.74
A35: 45966 | B35: DR | C35: Non-Sterling Transaction Fee | D35: -0.24 | E35: Expense | F35: Bank Fee | G35: Travel and Parking | H35: travel expenses | I35: Business | J35: 1 | K35: Yes | L35: =IF(AND($E35="Income",$I35="Business",$K35="Yes"),MAX($D35,0)*$J35,0) -> 0 | M35: =IF(AND($E35="Expense",OR($I35="Business",$I35="Mixed"),OR($K35="Yes",$K35="Stock")),ABS(MIN($D35,0))*$J35,0) -> 0.24 | N35: No VAT registered | O35: To find | R35: Outside 2026–27 | T35: Not reviewed | U35: 3618.77
A36: 45966 | B36: ))) | C36: INT'L 0014421530 FIERA MI RISTORAZIRHO EUR 10.00 @ 1.1376 Visa Rate | D36: -8.79 | E36: Expense | F36: Card | G36: Travel and Parking | H36: travel expenses | I36: Business | J36: 1 | K36: Yes | L36: =IF(AND($E36="Income",$I36="Business",$K36="Yes"),MAX($D36,0)*$J36,0) -> 0 | M36: =IF(AND($E36="Expense",OR($I36="Business",$I36="Mixed"),OR($K36="Yes",$K36="Stock")),ABS(MIN($D36,0))*$J36,0) -> 8.79 | N36: No VAT registered | O36: To find | R36: Outside 2026–27 | T36: Not reviewed | U36: 3619.01
A37: 45966 | B37: DR | C37: Non-Sterling Transaction Fee | D37: -0.21 | E37: Expense | F37: Bank Fee | G37: Travel and Parking | H37: travel expenses | I37: Business | J37: 1 | K37: Yes | L37: =IF(AND($E37="Income",$I37="Business",$K37="Yes"),MAX($D37,0)*$J37,0) -> 0 | M37: =IF(AND($E37="Expense",OR($I37="Business",$I37="Mixed"),OR($K37="Yes",$K37="Stock")),ABS(MIN($D37,0))*$J37,0) -> 0.21 | N37: No VAT registered | O37: To find | R37: Outside 2026–27 | T37: Not reviewed | U37: 3627.8
A38: 45966 | B38: ))) | C38: INT'L 0014421529 FIERA MI RISTORAZIRHO EUR 9.00 @ 1.1378 Visa Rate | D38: -7.91 | E38: Expense | F38: Card | G38: Travel and Parking | H38: travel expenses | I38: Business | J38: 1 | K38: Yes | L38: =IF(AND($E38="Income",$I38="Business",$K38="Yes"),MAX($D38,0)*$J38,0) -> 0 | M38: =IF(AND($E38="Expense",OR($I38="Business",$I38="Mixed"),OR($K38="Yes",$K38="Stock")),ABS(MIN($D38,0))*$J38,0) -> 7.91 | N38: No VAT registered | O38: To find | R38: Outside 2026–27 | T38: Not reviewed | U38: 3628.01
A39: 45967 | B39: DR | C39: Non-Sterling Transaction Fee | D39: -0.36 | E39: Expense | F39: Bank Fee | G39: Travel and Parking | H39: travel expenses | I39: Business | J39: 1 | K39: Yes | L39: =IF(AND($E39="Income",$I39="Business",$K39="Yes"),MAX($D39,0)*$J39,0) -> 0 | M39: =IF(AND($E39="Expense",OR($I39="Business",$I39="Mixed"),OR($K39="Yes",$K39="Stock")),ABS(MIN($D39,0))*$J39,0) -> 0.36 | N39: No VAT registered | O39: To find | R39: Outside 2026–27 | T39: Not reviewed | U39: 3783.84
A40: 45967 | B40: ))) | C40: INT'L 0021991948 AUTOGRILL 0546 SOMMA LOMBARD EUR 15.20 @ 1.1334 Visa Rate | D40: -13.41 | E40: Expense | F40: Card | G40: Travel and Parking | H40: travel expenses | I40: Business | J40: 1 | K40: Yes | L40: =IF(AND($E40="Income",$I40="Business",$K40="Yes"),MAX($D40,0)*$J40,0) -> 0 | M40: =IF(AND($E40="Expense",OR($I40="Business",$I40="Mixed"),OR($K40="Yes",$K40="Stock")),ABS(MIN($D40,0))*$J40,0) -> 13.41 | N40: No VAT registered | O40: To find | R40: Outside 2026–27 | T40: Not reviewed | U40: 3784.2
...

Sheet Dashboard
A1: DWB Trading — 2026–27 Bookkeeping Dashboard
A2: Current tax year only: 6 April 2026 to 5 April 2027
A4: Key figure | B4: Amount | D4: Review status | E4: Count | G4: Tax planning — run-rate estimate
A5: Business income — current tax year | B5: =SUMIFS(Transactions!$L$2:$L$228,Transactions!$A$2:$A$228,">="&DATE(2026,4,6),Transactions!$A$2:$A$228,"<="&DATE(2027,4,5)) -> 21997.92 | D5: Needs category review | E5: =COUNTIFS(Transactions!$G$2:$G$228,"Needs Review",Transactions!$A$2:$A$228,">="&DATE(2026,4,6),Transactions!$A$2:$A$228,"<="&DATE(2027,4,5)) -> 0 | G5: Latest transaction date | J5: =MAX(Transactions!A2:A228) -> 46220
A6: Allowable expenses — current tax year | B6: =SUMIFS(Transactions!$M$2:$M$228,Transactions!$A$2:$A$228,">="&DATE(2026,4,6),Transactions!$A$2:$A$228,"<="&DATE(2027,4,5)) -> 11010.57 | D6: Personal / excluded | E6: =COUNTIFS(Transactions!$I$2:$I$228,"Personal",Transactions!$A$2:$A$228,">="&DATE(2026,4,6),Transactions!$A$2:$A$228,"<="&DATE(2027,4,5))+COUNTIFS(Transactions!$I$2:$I$228,"Exclude",Transactions!$A$2:$A$228,">="&DATE(2026,4,6),Transactions!$A$2:$A$228,"<="&DATE(2027,4,5)) -> 6 | G6: Days recorded in tax year | J6: =MAX(J5-DATE(2026,4,6)+1,1) -> 103
A7: Profit recorded so far | B7: =MAX(B5-B6,0) -> 10987.35 | D7: Missing receipt | E7: =COUNTIFS(Transactions!$O$2:$O$228,"To find",Transactions!$A$2:$A$228,">="&DATE(2026,4,6),Transactions!$A$2:$A$228,"<="&DATE(2027,4,5)) -> 71 | G7: Profit recorded so far | J7: =B7 -> 10987.35
A8: Income Tax estimate on profit so far | B8: =MAX(MIN(B7,Lists!$L$3)-Lists!$L$2,0)*Lists!$L$4+MAX(B7-Lists!$L$3,0)*Lists!$L$5 -> 0 | D8: Accountant queries | E8: =COUNTIFS(Transactions!$T$2:$T$228,"Query for accountant",Transactions!$A$2:$A$228,">="&DATE(2026,4,6),Transactions!$A$2:$A$228,"<="&DATE(2027,4,5)) -> 0 | G8: Projected annual profit | J8: =IF(J6>0,J7/J6*365,0) -> 38935.755
A9: Class 4 NI estimate on profit so far | B9: =MAX(MIN(B7,Lists!$L$3)-Lists!$L$2,0)*Lists!$L$6+MAX(B7-Lists!$L$3,0)*Lists!$L$7 -> 0 | D9: Tax-year transactions | E9: =COUNTIFS(Transactions!$A$2:$A$228,">="&DATE(2026,4,6),Transactions!$A$2:$A$228,"<="&DATE(2027,4,5)) -> 116 | G9: Projected Income Tax | J9: =MAX(MIN(J8,Lists!$L$3)-Lists!$L$2,0)*Lists!$L$4+MAX(J8-Lists!$L$3,0)*Lists!$L$5 -> 5273.151
A10: Tax and NI estimate so far | B10: =B8+B9 -> 0 | D10: Latest bank balance | E10: =LOOKUP(2,1/(Transactions!U2:U228<>""),Transactions!U2:U228) -> 10518.93 | G10: Projected Class 4 NI | J10: =MAX(MIN(J8,Lists!$L$3)-Lists!$L$2,0)*Lists!$L$6+MAX(J8-Lists!$L$3,0)*Lists!$L$7 -> 1581.9453
G11: Suggested projected reserve | J11: =J9+J10 -> 6855.0963
A13: Important: this is an estimate and categorisation aid, not an HMRC submission. Review every amber item and let the accountant confirm allowable expenses, stock and employment status. | G13: Run-rate projection assumes the profit pace to the latest transaction date continues for the full year. It is a budgeting guide, not an amount currently payable.
A16: Quarter | B16: Income (£) | C16: Expenses (£) | D16: Profit (£)
A17: Q1: 6 Apr–5 Jul | B17: =SUMIF(Transactions!R$2:R$228,A17,Transactions!L$2:L$228) -> 15420.77 | C17: =SUMIF(Transactions!R$2:R$228,A17,Transactions!M$2:M$228) -> 9857.68 | D17: =B17-C17 -> 5563.09
A18: Q2: 6 Jul–5 Oct | B18: =SUMIF(Transactions!R$2:R$228,A18,Transactions!L$2:L$228) -> 6577.15 | C18: =SUMIF(Transactions!R$2:R$228,A18,Transactions!M$2:M$228) -> 1152.89 | D18: =B18-C18 -> 5424.26
A19: Q3: 6 Oct–5 Jan | B19: =SUMIF(Transactions!R$2:R$228,A19,Transactions!L$2:L$228) -> 0 | C19: =SUMIF(Transactions!R$2:R$228,A19,Transactions!M$2:M$228) -> 0 | D19: =B19-C19 -> 0
A20: Q4: 6 Jan–5 Apr | B20: =SUMIF(Transactions!R$2:R$228,A20,Transactions!L$2:L$228) -> 0 | C20: =SUMIF(Transactions!R$2:R$228,A20,Transactions!M$2:M$228) -> 0 | D20: =B20-C20 -> 0
A21: Full 2026–27 | B21: =SUM(B17:B20) -> 21997.92 | C21: =SUM(C17:C20) -> 11010.57 | D21: =B21-C21 -> 10987.35

Sheet MTD Summary
A1: MTD Quarterly Summary — Accountant Working Sheet
A4: Update | B4: Cumulative period | C4: Deadline | D4: Income (£) | E4: Expenses (£) | F4: Profit (£) | G4: Status / Notes
A5: Quarter 1 | B5: 6 Apr–5 Jul 2026 | C5: 46241 | D5: =SUMIFS(Transactions!$L$2:$L$228,Transactions!$A$2:$A$228,">="&DATE(2026,4,6),Transactions!$A$2:$A$228,"<="&DATE(2026,7,5)) -> 15420.77 | E5: =SUMIFS(Transactions!$M$2:$M$228,Transactions!$A$2:$A$228,">="&DATE(2026,4,6),Transactions!$A$2:$A$228,"<="&DATE(2026,7,5)) -> 9857.68 | F5: =D5-E5 -> 5563.09 | G5: Quarterly update due 7 Aug 2026 — no tax payment is due with this update
A6: Quarter 2 | B6: 6 Apr–5 Oct 2026 | C6: 46333 | D6: =SUMIFS(Transactions!$L$2:$L$228,Transactions!$A$2:$A$228,">="&DATE(2026,4,6),Transactions!$A$2:$A$228,"<="&DATE(2026,10,5)) -> 21997.92 | E6: =SUMIFS(Transactions!$M$2:$M$228,Transactions!$A$2:$A$228,">="&DATE(2026,4,6),Transactions!$A$2:$A$228,"<="&DATE(2026,10,5)) -> 11010.57 | F6: =D6-E6 -> 10987.35 | G6: Quarterly update due 7 Nov 2026
A7: Quarter 3 | B7: 6 Apr 2026–5 Jan 2027 | C7: 46425 | D7: =SUMIFS(Transactions!$L$2:$L$228,Transactions!$A$2:$A$228,">="&DATE(2026,4,6),Transactions!$A$2:$A$228,"<="&DATE(2027,1,5)) -> 21997.92 | E7: =SUMIFS(Transactions!$M$2:$M$228,Transactions!$A$2:$A$228,">="&DATE(2026,4,6),Transactions!$A$2:$A$228,"<="&DATE(2027,1,5)) -> 11010.57 | F7: =D7-E7 -> 10987.35 | G7: Quarterly update due 7 Feb 2027
A8: Quarter 4 | B8: 6 Apr 2026–5 Apr 2027 | C8: 46514 | D8: =SUMIFS(Transactions!$L$2:$L$228,Transactions!$A$2:$A$228,">="&DATE(2026,4,6),Transactions!$A$2:$A$228,"<="&DATE(2027,4,5)) -> 21997.92 | E8: =SUMIFS(Transactions!$M$2:$M$228,Transactions!$A$2:$A$228,">="&DATE(2026,4,6),Transactions!$A$2:$A$228,"<="&DATE(2027,4,5)) -> 11010.57 | F8: =D8-E8 -> 10987.35 | G8: Quarterly update due 7 May 2027
A9: Annual return | B9: 6 Apr 2026–5 Apr 2027 | C9: 46783 | D9: =D8 -> 21997.92 | E9: =E8 -> 11010.57 | F9: =F8 -> 10987.35 | G9: Final tax return and balancing payment due 31 Jan 2028
A11: Quarterly updates report cumulative income and expenses. They are not quarterly tax bills. The final Income Tax and National Insurance position is calculated on the annual return.

Sheet Bike Stock
A1: Bike ID / Reg | B1: Purchase Date | C1: Make / Model | D1: Purchase Price (£) | E1: Purchase Costs (£) | F1: Parts / Prep (£) | G1: Status | H1: Sale Date | I1: Sale Price (£) | J1: Gross Profit (£) | K1: Customer / Source | L1: Notes
J2: =IF(OR(G2<>"Sold",I2=""),"",I2-D2-E2-F2)
J3: =IF(OR(G3<>"Sold",I3=""),"",I3-D3-E3-F3)
J4: =IF(OR(G4<>"Sold",I4=""),"",I4-D4-E4-F4)
J5: =IF(OR(G5<>"Sold",I5=""),"",I5-D5-E5-F5)
J6: =IF(OR(G6<>"Sold",I6=""),"",I6-D6-E6-F6)
J7: =IF(OR(G7<>"Sold",I7=""),"",I7-D7-E7-F7)
J8: =IF(OR(G8<>"Sold",I8=""),"",I8-D8-E8-F8)
J9: =IF(OR(G9<>"Sold",I9=""),"",I9-D9-E9-F9)
J10: =IF(OR(G10<>"Sold",I10=""),"",I10-D10-E10-F10)
J11: =IF(OR(G11<>"Sold",I11=""),"",I11-D11-E11-F11)
J12: =IF(OR(G12<>"Sold",I12=""),"",I12-D12-E12-F12)
J13: =IF(OR(G13<>"Sold",I13=""),"",I13-D13-E13-F13)
... J101: =IF(OR(G101<>"Sold",I101=""),"",I101-D101-E101-F101)

Sheet Mileage
A1: Date | B1: Journey / Purpose | C1: From | D1: To | E1: Vehicle | F1: Business Miles | G1: Rate (£/mile) | H1: Allowable Mileage (£) | I1: Notes
G2: =IF(E2="Motorcycle",0.24,IF(F2<=10000,0.55,0.25)) -> 0.55 | H2: =IF(F2="","",F2*G2)
G3: =IF(E3="Motorcycle",0.24,IF(F3<=10000,0.55,0.25)) -> 0.55 | H3: =IF(F3="","",F3*G3)
G4: =IF(E4="Motorcycle",0.24,IF(F4<=10000,0.55,0.25)) -> 0.55 | H4: =IF(F4="","",F4*G4)
G5: =IF(E5="Motorcycle",0.24,IF(F5<=10000,0.55,0.25)) -> 0.55 | H5: =IF(F5="","",F5*G5)
G6: =IF(E6="Motorcycle",0.24,IF(F6<=10000,0.55,0.25)) -> 0.55 | H6: =IF(F6="","",F6*G6)
G7: =IF(E7="Motorcycle",0.24,IF(F7<=10000,0.55,0.25)) -> 0.55 | H7: =IF(F7="","",F7*G7)
G8: =IF(E8="Motorcycle",0.24,IF(F8<=10000,0.55,0.25)) -> 0.55 | H8: =IF(F8="","",F8*G8)
G9: =IF(E9="Motorcycle",0.24,IF(F9<=10000,0.55,0.25)) -> 0.55 | H9: =IF(F9="","",F9*G9)
G10: =IF(E10="Motorcycle",0.24,IF(F10<=10000,0.55,0.25)) -> 0.55 | H10: =IF(F10="","",F10*G10)
G11: =IF(E11="Motorcycle",0.24,IF(F11<=10000,0.55,0.25)) -> 0.55 | H11: =IF(F11="","",F11*G11)
G12: =IF(E12="Motorcycle",0.24,IF(F12<=10000,0.55,0.25)) -> 0.55 | H12: =IF(F12="","",F12*G12)
G13: =IF(E13="Motorcycle",0.24,IF(F13<=10000,0.55,0.25)) -> 0.55 | H13: =IF(F13="","",F13*G13)
... G301: =IF(E301="Motorcycle",0.24,IF(F301<=10000,0.55,0.25)) -> 0.55 | H301: =IF(F301="","",F301*G301)

Sheet Lists
A1: Categories | B1: Payment methods | C1: Business status | D1: Allowable? | E1: Receipt status | G1: Review status | H1: Income/Expense/Transfer | I1: VAT treatment | K1: 2026–27 tax assumptions | L1: Value | N1: Useful category guidance
A2: SmartFobs Sales | B2: Card | C2: Business | D2: Yes | E2: Yes | G2: Not reviewed | H2: Income | I2: No VAT registered | K2: Personal Allowance | L2: 12570 | N2: Expense | O2: Use category | P2: Example note
A3: Labour / Contract Income | B3: Bank Transfer | C3: Personal | D3: No | E3: No | G3: Reviewed | H3: Expense | I3: VAT included | K3: Basic-rate upper total income | L3: 50270 | N3: Workshop T-shirts/uniform | O3: Work Clothing / Uniform | P3: Regatta shirts bought only for workshop use
A4: Bike Sales | B4: Cash | C4: Mixed | D4: Review | E4: Not needed | G4: Query for accountant | H4: Transfer | I4: Zero-rated | K4: Income Tax basic rate | L4: 0.2 | N4: Flights/trains for supplier trip | O4: Travel and Parking | P4: Milan supplier and parts sourcing trip
A5: Other Business Income | B5: Direct Debit | C5: Exclude | D5: Stock | E5: To find | G5: Adjusted | I5: Outside scope | K5: Income Tax higher rate | L5: 0.4 | N5: Hotel paid by you | O5: Accommodation | P5: Business accommodation for supplier trip
A6: Bike Purchases (Stock) | B6: Standing Order | C6: Review | I6: Unknown | K6: Class 4 NI main rate | L6: 0.06 | N6: Meals while away for business | O6: Travel and Subsistence | P6: Subsistence during two-day business trip
A7: Parts and Materials | B7: Bank Fee | K7: Class 4 NI upper rate | L7: 0.02 | N7: Trade fair/supplier visit fees | O7: Trade Shows / Supplier Sourcing | P7: Supplier research and product sourcing
A8: Keys / Stock / Small Parts | B8: Cheque
A9: Fuel / Vehicle Costs | B9: Other | K9: MTD standard periods | L9: Deadline
A10: Postage and Courier | K10: 6 Apr–5 Jul 2026 | L10: 46241
A11: Tools and Equipment | K11: 6 Apr–5 Oct 2026 | L11: 46333
A12: Software and Subscriptions | K12: 6 Apr 2026–5 Jan 2027 | L12: 46425
A13: Advertising and Marketing
A14: Phone and Internet
A15: Insurance
A16: Bank Charges
A17: Accountancy and Legal
A18: Rent and Premises
A19: Travel and Parking
A20: Training
A21: Repairs and Maintenance
A22: Transfer Between Own Accounts
A23: Owner Drawings
A24: Personal / Non-business
... A31: Trade Shows / Supplier Sourcing

Sheet Instructions
A1: How to finish this workbook before sending it to an accountant
A4: Step | B4: What to do
A5: 1 | B5: Open Transactions and work through every amber “Needs Review” row.
A6: 2 | B6: Choose the correct Category, Business Status, Business Use %, Allowable? and Receipt Status.
A7: 3 | B7: Transfers between your own accounts and money taken personally should not be treated as business expenses.
A8: 4 | B8: For mixed costs, enter the business percentage only (for example 50%).
A9: 5 | B9: Enter each motorcycle bought for resale on Bike Stock, including unsold stock at 5 April.
A10: 6 | B10: Use Mileage only if claiming simplified mileage. Do not also claim the same vehicle’s fuel/running costs.
A11: 7 | B11: Add a short note or receipt/file link where the accountant may need evidence.
A12: 8 | B12: Check Dashboard and MTD Summary, then send the whole .xlsx file plus receipts/statements to the accountant.
A14: Important point | B14: Explanation
A15: MTD submission | B15: This workbook prepares records but does not submit them to HMRC.
A16: Tax estimate | B16: The dashboard estimate assumes England/Wales/Northern Ireland standard allowance and bands and no other taxable income or reliefs.
... A32: Work clothing | B32: Use Work Clothing / Uniform for clothing bought specifically for workshop or uniform use; keep receipts and explain the purpose.

Sheet Tax Estimate
A1: DWB Trading — 2026–27 Tax Estimate
A3: Recorded position | B3: Amount | D3: Run-rate planning | E3: Amount
A4: Income recorded in 2026–27 | B4: =Dashboard!B5 -> 21997.92 | D4: Latest transaction date | E4: =Dashboard!J5 -> 46220
A5: Allowable expenses recorded | B5: =Dashboard!B6 -> 11010.57 | D5: Days recorded | E5: =Dashboard!J6 -> 103
A6: Profit recorded so far | B6: =Dashboard!B7 -> 10987.35 | D6: Projected annual profit | E6: =Dashboard!J8 -> 38935.755
A7: Estimated Income Tax so far | B7: =Dashboard!B8 -> 0 | D7: Projected Income Tax | E7: =Dashboard!J9 -> 5273.151
A8: Estimated Class 4 NI so far | B8: =Dashboard!B9 -> 0 | D8: Projected Class 4 NI | E8: =Dashboard!J10 -> 1581.9453
A9: Estimated total tax and NI so far | B9: =Dashboard!B10 -> 0 | D9: Suggested projected reserve | E9: =Dashboard!J11 -> 6855.0963
A11: Important: the recorded estimate applies the annual Personal Allowance to the profit entered so far, so it may show £0 until profit exceeds the threshold. The run-rate section is for saving and budgeting only. Other personal income, student loans, pension contributions, benefits, capital allowances and accountant adjustments can change the final bill.
A15: 2026–27 assumptions | B15: Value | D15: Official source | E15: URL | F15: Checked
A16: Personal Allowance | B16: 12570 | D16: Income Tax rates | E16: https://www.gov.uk/income-tax-rates | F16: 19 Jul 2026
A17: Higher-rate threshold | B17: 50270 | D17: Self-employed NI rates | E17: https://www.gov.uk/self-employed-national-insurance-rates | F17: 19 Jul 2026
A18: Income Tax basic rate | B18: 0.2 | D18: MTD quarterly updates | E18: https://www.gov.uk/guidance/use-making-tax-digital-for-income-tax/send-quarterly-updates | F18: 19 Jul 2026
A19: Class 4 NI main rate | B19: 0.06
